<?xml version="1.0" ?>
<!-- =================================================================================== -->
<!-- |    This document was autogenerated by xacro from /home/cloudrobot2/catkin_ws/src/twc-stable-push-task/description/push_description/urdf/picking.xacro | -->
<!-- |    EDITING THIS FILE BY HAND IS NOT RECOMMENDED                                 | -->
<!-- =================================================================================== -->
<robot name="picking">
    <!-- robotiq, calibration, hanyang -->
    <!-- [rad] -->
    <!-- [0 ~ 1.5] [rad] -->
    <!-- true, false -->
    <!-- world base link -->
    <link name="world_base" />
    <!-- table -->
    <link name="table_link">
        <visual>
            <origin rpy="0 0 1.5707963267948966" xyz="0 0 0" />
            <geometry>
                <mesh filename="package://honeycomb_and_plate_description/meshes/honeycomb_table_simplified.dae" />
            </geometry>
            <material name="table_link_material">
                <color rgba="0.5 0.5 0.5 1" />
            </material>
        </visual>
        <collision>
            <origin rpy="0.0 0.0 0.0" xyz="0.0 0.0 -0.05" />
            <geometry>
                <box size="1.6 0.8 0.1" />
            </geometry>
            <origin rpy="0 0 0" xyz="0 0 0" />
        </collision>
        <inertial>
            <mass value="0.1" />
            <origin xyz="0 0 0" rpy="0 0 0" />
            <inertia ixx="0.03" iyy="0.03" izz="0.03" ixy="0.0" ixz="0.0" iyz="0.0" />
        </inertial>
    </link>
    <!-- plate -->
    <link name="plate_link">
        <visual>
            <origin rpy="0 0 0" xyz="0 0 0.354" />
            <geometry>
                <box size="1.6 0.8 0.708" />
            </geometry>
            <material name="plate_link">
                <color rgba="0.8 0.8 0.8 1" />
            </material>
        </visual>
    </link>
    <joint name="plate_joint" type="fixed">
        <parent link="table_link" />
        <child link="plate_link" />
        <origin rpy="0 0 0" xyz="0 0 -0.798" />
    </joint>
    <joint name="world-env_joint" type="fixed">
        <parent link="world_base" />
        <child link="table_link" />
        <origin rpy="0 0 0" xyz="0 0 0" />
    </joint>
    <!-- base link -->
    <link name="manipulator_base_link" />
    <material name="black">
        <color rgba="0.0 0.0 0.0 1.0" />
    </material>
    <material name="white">
        <color rgba="1.0 1.0 1.0 1.0" />
    </material>
    <material name="orange">
        <color rgba="1.0 0.4 0.0 1.0" />
    </material>
    <material name="dr_gray">
        <color rgba="0.490 0.490 0.486 1.0" />
    </material>
    <material name="dr_white">
        <color rgba="0.941 0.941 0.941 1.0" />
    </material>
    <link name="base_0">
        <inertial>
            <mass value="4.12" />
            <origin xyz="-3.4e-05   -0.004815    0.048482" />
            <inertia ixx="0.016331" ixy="-6.4837e-06" ixz="2.0048e-06" iyy="0.014945" iyz="-0.00051686" izz="0.022577" />
        </inertial>
        <visual>
            <origin rpy="0 0 0" xyz="0 0 0" />
            <geometry>
                <mesh filename="package://dsr_description/meshes/m1013_white/MF1013_0_0.dae" scale="0.001 0.001 0.001" />
            </geometry>
        </visual>
    </link>
    <!-- joint 1 -->
    <joint name="joint1" type="revolute">
        <parent link="base_0" />
        <child link="link1" />
        <origin rpy="0 0 0" xyz="0 0 0.1525" />
        <axis xyz="0 0 1" />
        <limit effort="346" lower="-6.2832" upper="6.2832" velocity="2.0944" />
        <dynamics friction="0" />
    </joint>
    <link name="link1">
        <inertial>
            <mass value="7.8" />
            <origin xyz="0.000119      0.0428   -0.006383" rpy="0 0 0" />
            <inertia ixx="0.04506" ixy="4.1126e-05" ixz="-5.2533e-05" iyy="0.029679" iyz="-0.0019959" izz="0.047056" />
        </inertial>
        <collision>
            <geometry>
                <cylinder length="0.2" radius="0.1" />
            </geometry>
        </collision>
        <visual>
            <origin rpy="0 0 0" xyz="0 0 0" />
            <geometry>
                <mesh filename="package://dsr_description/meshes/m1013_white/MF1013_1_0.dae" scale="0.001 0.001 0.001" />
            </geometry>
        </visual>
    </link>
    <!-- joint2 -->
    <joint name="joint2" type="revolute">
        <parent link="link1" />
        <child link="link2" />
        <origin rpy="0 -1.571 -1.571" xyz="0 0.0345 0" />
        <axis xyz="0 0 1" />
        <limit effort="346" lower="-6.2832" upper="6.2832" velocity="2.0944" />
        <dynamics friction="0" />
    </joint>
    <link name="link2">
        <inertial>
            <mass value="10.83" />
            <origin xyz="0.25973    -5.3e-05     0.15782" rpy="0 0 0" />
            <inertia ixx="0.037586" ixy="-0.00036999" ixz="-0.0069927" iyy="0.84943" iyz="4.0201e-05" izz="0.85021" />
        </inertial>
        <collision>
            <origin rpy="0 -1.571 0" xyz="0.3 0 0.1525" />
            <geometry>
                <cylinder length="0.75" radius="0.08" />
            </geometry>
        </collision>
        <visual>
            <origin rpy="0 0 0" xyz="0 0 0" />
            <geometry>
                <mesh filename="package://dsr_description/meshes/m1013_white/MF1013_2_0.dae" scale="0.001 0.001 0.001" />
            </geometry>
        </visual>
        <visual>
            <origin rpy="0 0 0" xyz="0 0 0" />
            <geometry>
                <mesh filename="package://dsr_description/meshes/m1013_white/MF1013_2_1.dae" scale="0.001 0.001 0.001" />
            </geometry>
        </visual>
        <visual>
            <origin rpy="0 0 0" xyz="0 0 0" />
            <geometry>
                <mesh filename="package://dsr_description/meshes/m1013_white/MF1013_2_2.dae" scale="0.001 0.001 0.001" />
            </geometry>
        </visual>
    </link>
    <!-- joint3 -->
    <joint name="joint3" type="revolute">
        <parent link="link2" />
        <child link="link3" />
        <origin rpy="0 0 1.571" xyz="0.62 0 0" />
        <axis xyz="0 0 1" />
        <limit effort="163" lower="-2.7925" upper="2.7925" velocity="3.1416" />
        <dynamics friction="0" />
    </joint>
    <link name="link3">
        <inertial>
            <mass value="3.68" />
            <origin xyz="-1.5e-05   -0.006702    0.044608" />
            <inertia ixx="0.018748" ixy="7.8071e-06" ixz="-5.0324e-06" iyy="0.018972" iyz="-0.00099342" izz="0.011502" />
        </inertial>
        <visual>
            <origin rpy="0 0 0" xyz="0 0 0" />
            <geometry>
                <mesh filename="package://dsr_description/meshes/m1013_white/MF1013_3_0.dae" scale="0.001 0.001 0.001" />
            </geometry>
        </visual>
    </link>
    <!-- joint4 -->
    <joint name="joint4" type="revolute">
        <parent link="link3" />
        <child link="link4" />
        <origin rpy="1.571 0 0" xyz="0 -0.559 0" />
        <axis xyz="0 0 1" />
        <limit effort="50" lower="-6.2832" upper="6.2832" velocity="3.927" />
        <dynamics friction="0" />
    </joint>
    <link name="link4">
        <inertial>
            <mass value="3.82" />
            <origin xyz="7.1e-05    0.091879    -0.18252" rpy="0 0 0" />
            <inertia ixx="0.19063" ixy="-1.8037e-05" ixz="-3.8576e-05" iyy="0.17268" iyz="-0.052996" izz="0.030386" />
        </inertial>
        <collision>
            <origin rpy="-0.55 0 0" xyz="0 0.07 -0.3" />
            <geometry>
                <cylinder length="0.4" radius="0.07" />
            </geometry>
        </collision>
        <visual>
            <origin rpy="0 0 0" xyz="0 0 0" />
            <geometry>
                <mesh filename="package://dsr_description/meshes/m1013_white/MF1013_4_0.dae" scale="0.001 0.001 0.001" />
            </geometry>
        </visual>
        <visual>
            <origin rpy="0 0 0" xyz="0 0 0" />
            <geometry>
                <mesh filename="package://dsr_description/meshes/m1013_white/MF1013_4_1.dae" scale="0.001 0.001 0.001" />
            </geometry>
        </visual>
    </link>
    <!-- joint5 -->
    <joint name="joint5" type="revolute">
        <parent link="link4" />
        <child link="link5" />
        <origin rpy="-1.571 0 0" xyz="0 0 0" />
        <axis xyz="0 0 1" />
        <limit effort="50" lower="-6.2832" upper="6.2832" velocity="3.927" />
        <dynamics friction="0" />
    </joint>
    <link name="link5">
        <inertial>
            <mass value="2.82" />
            <origin xyz="-0.000273    0.003651    0.032088" rpy="0 0 0" />
            <inertia ixx="0.015583" ixy="2.135e-05" ixz="-5.1895e-06" iyy="0.011519" iyz="0.00042553" izz="0.0088671" />
        </inertial>
        <collision>
            <origin rpy="1.571 0 0" xyz="0 0 0" />
            <geometry>
                <cylinder length="0.15" radius="0.08" />
            </geometry>
        </collision>
        <visual>
            <origin rpy="0 0 0" xyz="0 0 0" />
            <geometry>
                <mesh filename="package://dsr_description/meshes/m1013_white/MF1013_5_0.dae" scale="0.001 0.001 0.001" />
            </geometry>
        </visual>
    </link>
    <!-- joint6 -->
    <joint name="joint6" type="revolute">
        <parent link="link5" />
        <child link="link6" />
        <origin rpy="1.571 0 0" xyz="0 -0.121 0" />
        <axis xyz="0 0 1" />
        <limit effort="50" lower="-6.2832" upper="6.2832" velocity="3.927" />
        <dynamics friction="0" />
    </joint>
    <link name="link6">
        <inertial>
            <mass value="1.16" />
            <origin xyz="-0.000292       7e-06     -0.0539" />
            <inertia ixx="0.0048282" ixy="4.1298e-06" ixz="6.9879e-06" iyy="0.0059519" iyz="4.252e-06" izz="0.0061263" />
        </inertial>
        <visual>
            <origin rpy="0 0 0" xyz="0 0 0" />
            <geometry>
                <mesh filename="package://dsr_description/meshes/m1013_white/MF1013_6_0.dae" scale="0.001 0.001 0.001" />
            </geometry>
        </visual>
    </link>
    <!-- Transmission 1 -->
    <transmission name="tran1">
        <type>transmission_interface/SimpleTransmission</type>
        <joint name="joint1">
            <hardwareInterface>hardware_interface/PositionJointInterface</hardwareInterface>
        </joint>
        <actuator name="motor1">
            <hardwareInterface>hardware_interface/PositionJointInterface</hardwareInterface>
            <mechanicalReduction>1</mechanicalReduction>
        </actuator>
    </transmission>
    <!-- Transmission 2 -->
    <transmission name="tran2">
        <type>transmission_interface/SimpleTransmission</type>
        <joint name="joint2">
            <hardwareInterface>hardware_interface/PositionJointInterface</hardwareInterface>
        </joint>
        <actuator name="motor2">
            <hardwareInterface>hardware_interface/PositionJointInterface</hardwareInterface>
            <mechanicalReduction>1</mechanicalReduction>
        </actuator>
    </transmission>
    <!-- Transmission 3 -->
    <transmission name="tran3">
        <type>transmission_interface/SimpleTransmission</type>
        <joint name="joint3">
            <hardwareInterface>hardware_interface/PositionJointInterface</hardwareInterface>
        </joint>
        <actuator name="motor3">
            <hardwareInterface>hardware_interface/PositionJointInterface</hardwareInterface>
            <mechanicalReduction>1</mechanicalReduction>
        </actuator>
    </transmission>
    <!-- Transmission 4 -->
    <transmission name="tran4">
        <type>transmission_interface/SimpleTransmission</type>
        <joint name="joint4">
            <hardwareInterface>hardware_interface/PositionJointInterface</hardwareInterface>
        </joint>
        <actuator name="motor4">
            <hardwareInterface>hardware_interface/PositionJointInterface</hardwareInterface>
            <mechanicalReduction>1</mechanicalReduction>
        </actuator>
    </transmission>
    <!-- Transmission 5 -->
    <transmission name="tran5">
        <type>transmission_interface/SimpleTransmission</type>
        <joint name="joint5">
            <hardwareInterface>hardware_interface/PositionJointInterface</hardwareInterface>
        </joint>
        <actuator name="motor5">
            <hardwareInterface>hardware_interface/PositionJointInterface</hardwareInterface>
            <mechanicalReduction>1</mechanicalReduction>
        </actuator>
    </transmission>
    <!-- Transmission 6 -->
    <transmission name="tran6">
        <type>transmission_interface/SimpleTransmission</type>
        <joint name="joint6">
            <hardwareInterface>hardware_interface/PositionJointInterface</hardwareInterface>
        </joint>
        <actuator name="motor6">
            <hardwareInterface>hardware_interface/PositionJointInterface</hardwareInterface>
            <mechanicalReduction>1</mechanicalReduction>
        </actuator>
    </transmission>
    <!-- Base -->
    <selfCollide>true</selfCollide>
    <gazebo reference="dsr01">
        <selfCollide>true</selfCollide>
        <plugin name="gazebo_ros_control">
            <robotNamespace>/</robotNamespace>
        </plugin>
    </gazebo>
    <gazebo reference="base_0">
        <selfCollide>true</selfCollide>
        <kp>1000000.0</kp>
        <kd>100.0</kd>
        <mu1>30.0</mu1>
        <mu2>30.0</mu2>
        <maxVel>1.0</maxVel>
        <minDepth>0.001</minDepth>
    </gazebo>
    <!-- Link1 -->
    <gazebo reference="link1">
        <selfCollide>true</selfCollide>
        <kp>1000000.0</kp>
        <kd>100.0</kd>
        <mu1>30.0</mu1>
        <mu2>30.0</mu2>
        <maxVel>1.0</maxVel>
        <minDepth>0.001</minDepth>
    </gazebo>
    <!-- Link2 -->
    <gazebo reference="link2">
        <selfCollide>true</selfCollide>
        <kp>1000000.0</kp>
        <kd>100.0</kd>
        <mu1>30.0</mu1>
        <mu2>30.0</mu2>
        <maxVel>1.0</maxVel>
        <minDepth>0.001</minDepth>
    </gazebo>
    <!-- Link3 -->
    <gazebo reference="link3">
        <selfCollide>true</selfCollide>
        <kp>1000000.0</kp>
        <kd>100.0</kd>
        <mu1>30.0</mu1>
        <mu2>30.0</mu2>
        <maxVel>1.0</maxVel>
        <minDepth>0.001</minDepth>
    </gazebo>
    <!-- Link4 -->
    <gazebo reference="link4">
        <selfCollide>true</selfCollide>
        <kp>1000000.0</kp>
        <kd>100.0</kd>
        <mu1>30.0</mu1>
        <mu2>30.0</mu2>
        <maxVel>1.0</maxVel>
        <minDepth>0.001</minDepth>
    </gazebo>
    <!-- Link5 -->
    <gazebo reference="link5">
        <selfCollide>true</selfCollide>
        <kp>1000000.0</kp>
        <kd>100.0</kd>
        <mu1>30.0</mu1>
        <mu2>30.0</mu2>
        <maxVel>1.0</maxVel>
        <minDepth>0.001</minDepth>
    </gazebo>
    <!-- Link6 -->
    <gazebo reference="link6">
        <selfCollide>true</selfCollide>
        <kp>1000000.0</kp>
        <kd>100.0</kd>
        <mu1>30.0</mu1>
        <mu2>30.0</mu2>
        <maxVel>1.0</maxVel>
        <minDepth>0.001</minDepth>
    </gazebo>
    <!-- ros_control plugin -->
    <gazebo>
        <selfCollide>true</selfCollide>
        <plugin filename="libgazebo_ros_control.so" name="gazebo_ros_control">
            <robotNamespace>/m1013_</robotNamespace>
            <controlPeriod>0.001</controlPeriod>
            <robotSimType>gazebo_ros_control/DefaultRobotHWSim</robotSimType>
            <legacyModeNS>true</legacyModeNS>
        </plugin>
    </gazebo>
    <joint name="world-m1013_joint" type="fixed">
        <origin rpy="0 0 0" xyz="0 0 0" />
        <parent link="manipulator_base_link" />
        <child link="base_0" />
    </joint>
    <joint name="table-manipulator_joint" type="fixed">
        <parent link="world_base" />
        <child link="manipulator_base_link" />
        <origin rpy="0.0000 0.0000 3.141592653589793" xyz="-0.6875 -0.0125 0.0000" />
    </joint>
    <link name="hanyang_base_link">
        <inertial>
            <origin rpy="0 0 0" xyz="0.0032794 0.0036243 -0.085843" />
            <mass value="1.1991" />
            <inertia ixx="0.0032705" ixy="-8.8997E-06" ixz="5.8891E-09" iyy="0.0032572" iyz="-1.1733E-07" izz="0.0061866" />
        </inertial>
        <visual>
            <origin rpy="0 0 0" xyz="0 0 0" />
            <geometry>
                <mesh filename="package://hanyang_gripper/meshes/base_link.STL" />
            </geometry>
            <material name="">
                <color rgba="0.79216 0.81961 0.93333 1" />
            </material>
        </visual>
        <collision>
            <origin rpy="0 0 0" xyz="0 0 0" />
            <geometry>
                <mesh filename="package://hanyang_gripper/meshes/base_link.STL" />
            </geometry>
        </collision>
    </link>
    <link name="finger_hinge_1_link">
        <inertial>
            <origin rpy="0 0 0" xyz="0.065641 -0.0079398 -0.0097225" />
            <mass value="0.075006" />
            <inertia ixx="2.2862E-05" ixy="-4.1935E-06" ixz="-1.113E-06" iyy="2.0983E-05" iyz="-2.3625E-06" izz="3.2464E-05" />
        </inertial>
        <visual>
            <origin rpy="0 0 0" xyz="0 0 0" />
            <geometry>
                <mesh filename="package://hanyang_gripper/meshes/finger_hinge_1_link.STL" />
            </geometry>
            <material name="">
                <color rgba="0.79216 0.81961 0.93333 1" />
            </material>
        </visual>
    </link>
    <joint name="finger_hinge_1_joint" type="prismatic">
        <origin rpy="0 0 -3.1416" xyz="0.13675 -0.0335 -0.115" />
        <parent link="hanyang_base_link" />
        <child link="finger_hinge_1_link" />
        <axis xyz="-1 0 0" />
        <limit effort="10" lower="0" upper="0.129" velocity="10" />
    </joint>
    <link name="finger_hinge_2_link">
        <inertial>
            <origin rpy="0 0 0" xyz="-0.0028372 -2.095E-05 0.057266" />
            <mass value="0.067705" />
            <inertia ixx="1.3529E-05" ixy="1.1024E-06" ixz="-2.9156E-06" iyy="2.022E-05" iyz="7.2143E-07" izz="1.741E-05" />
        </inertial>
        <visual>
            <origin rpy="0 0 0" xyz="0 0 0" />
            <geometry>
                <mesh filename="package://hanyang_gripper/meshes/finger_hinge_2_link.STL" />
            </geometry>
            <material name="">
                <color rgba="0.79216 0.81961 0.93333 1" />
            </material>
        </visual>
    </link>
    <joint name="finger_hinge_2_joint" type="revolute">
        <origin rpy="-3.1416 0 -3.1416" xyz="0.060883 -0.034 -0.0408" />
        <parent link="finger_hinge_1_link" />
        <child link="finger_hinge_2_link" />
        <axis xyz="0 1 0" />
        <limit effort="10" lower="-1.570796" upper="0" velocity="10" />
    </joint>
    <link name="finger_hinge_3_link">
        <inertial>
            <origin rpy="0 0 0" xyz="0.005275 0.0017219 0.027803" />
            <mass value="0.024551" />
            <inertia ixx="2.8212E-06" ixy="4.4824E-09" ixz="1.3164E-06" iyy="5.5805E-06" iyz="-2.68E-08" izz="5.0262E-06" />
        </inertial>
        <visual>
            <origin rpy="0 0 0" xyz="0 0 0" />
            <geometry>
                <mesh filename="package://hanyang_gripper/meshes/finger_hinge_3_link.STL" />
            </geometry>
            <material name="">
                <color rgba="0.79216 0.81961 0.93333 1" />
            </material>
        </visual>
    </link>
    <joint name="finger_hinge_3_joint" type="revolute">
        <origin rpy="0 0 0" xyz="-0.013 0.00125 0.1269" />
        <parent link="finger_hinge_2_link" />
        <child link="finger_hinge_3_link" />
        <axis xyz="0 -1 0" />
        <limit effort="10" lower="-0.13963" upper="0.349065777777778" velocity="10" />
    </joint>
    <link name="finger_1_1_link">
        <inertial>
            <origin rpy="0 0 0" xyz="0.065932 -0.02114 -0.050052" />
            <mass value="0.15457" />
            <inertia ixx="3.8904E-05" ixy="-1.1423E-06" ixz="-2.8992E-06" iyy="4.546E-05" iyz="-7.4443E-07" izz="4.8395E-05" />
        </inertial>
        <visual>
            <origin rpy="0 0 0" xyz="0 0 0" />
            <geometry>
                <mesh filename="package://hanyang_gripper/meshes/finger_1_1_link.STL" />
            </geometry>
            <material name="">
                <color rgba="0.79216 0.81961 0.93333 1" />
            </material>
        </visual>
    </link>
    <joint name="finger_1_1_joint" type="prismatic">
        <origin rpy="0 0 1.0472" xyz="-0.097387 -0.10168 -0.115" />
        <parent link="hanyang_base_link" />
        <child link="finger_1_1_link" />
        <axis xyz="-1 0 0" />
        <limit effort="10" lower="0" upper="0.129" velocity="10" />
    </joint>
    <link name="finger_1_2_link">
        <inertial>
            <origin rpy="0 0 0" xyz="-0.010542 0.0017219 -0.027803" />
            <mass value="0.024551" />
            <inertia ixx="2.8212E-06" ixy="-4.4826E-09" ixz="1.3164E-06" iyy="5.5805E-06" iyz="2.6801E-08" izz="5.0262E-06" />
        </inertial>
        <visual>
            <origin rpy="0 0 0" xyz="0 0 0" />
            <geometry>
                <mesh filename="package://hanyang_gripper/meshes/finger_1_2_link.STL" />
            </geometry>
            <material name="">
                <color rgba="0.79216 0.81961 0.93333 1" />
            </material>
        </visual>
    </link>
    <joint name="finger_1_2_joint" type="revolute">
        <origin rpy="0 0 0" xyz="0.07675 -0.03275 -0.168" />
        <parent link="finger_1_1_link" />
        <child link="finger_1_2_link" />
        <axis xyz="0 -1 0" />
        <limit effort="10" lower="-0.13963" upper="0.349065777777778" velocity="10" />
    </joint>
    <link name="finger_2_1_link">
        <inertial>
            <origin rpy="0 0 0" xyz="0.065932 -0.02114 -0.050052" />
            <mass value="0.15457" />
            <inertia ixx="3.8904E-05" ixy="-1.1423E-06" ixz="-2.8992E-06" iyy="4.546E-05" iyz="-7.4443E-07" izz="4.8395E-05" />
        </inertial>
        <visual>
            <origin rpy="0 0 0" xyz="0 0 0" />
            <geometry>
                <mesh filename="package://hanyang_gripper/meshes/finger_2_1_link.STL" />
            </geometry>
            <material name="">
                <color rgba="0.79216 0.81961 0.93333 1" />
            </material>
        </visual>
    </link>
    <joint name="finger_2_1_joint" type="prismatic">
        <origin rpy="0 0 -1.0472" xyz="-0.039363 0.13518 -0.115" />
        <parent link="hanyang_base_link" />
        <child link="finger_2_1_link" />
        <axis xyz="-1 0 0" />
        <limit effort="10" lower="0" upper="0.129" velocity="10" />
    </joint>
    <link name="finger_2_2_link">
        <inertial>
            <origin rpy="0 0 0" xyz="-0.010542 0.0017219 -0.027803" />
            <mass value="0.024551" />
            <inertia ixx="2.8212E-06" ixy="-4.4824E-09" ixz="1.3164E-06" iyy="5.5805E-06" iyz="2.68E-08" izz="5.0262E-06" />
        </inertial>
        <visual>
            <origin rpy="0 0 0" xyz="0 0 0" />
            <geometry>
                <mesh filename="package://hanyang_gripper/meshes/finger_2_2_link.STL" />
            </geometry>
            <material name="">
                <color rgba="0.79216 0.81961 0.93333 1" />
            </material>
        </visual>
    </link>
    <joint name="finger_2_2_joint" type="revolute">
        <origin rpy="0 0 0" xyz="0.07675 -0.03275 -0.168" />
        <parent link="finger_2_1_link" />
        <child link="finger_2_2_link" />
        <axis xyz="0 -1 0" />
        <limit effort="10" lower="-0.13963" upper="0.349065777777778" velocity="10" />
    </joint>
    <link name="grasp_point">
        <visual>
            <origin rpy="0 0 0" xyz="0 0 0" />
            <geometry>
                <box size="0.015 0.015 0.015" />
            </geometry>
            <material name="grasp_point">
                <color rgba="1 0 1 0.1" />
            </material>
        </visual>
    </link>
    <joint name="grasp_point_base" type="fixed">
        <parent link="hanyang_base_link" />
        <child link="grasp_point" />
        <origin rpy="0 0 0" xyz="0 0 -0.343421" />
    </joint>
    <joint name="m1013-mount_joint" type="fixed">
        <parent link="link6" />
        <child link="hanyang_base_link" />
        <origin rpy="3.141592653589793 0 0" xyz="0 0 0" />
    </joint>
    <!-- material color set -->
    <material name="camera_black">
        <color rgba="0.0 0.0 0.0 1.0" />
    </material>
    <material name="camera_white">
        <color rgba="1.0 1.0 1.0 1.0" />
    </material>
    <material name="camera_light_gray">
        <color rgba="0.7 0.7 0.7 1.0" />
    </material>
    <material name="camera_dark_gray">
        <color rgba="0.3 0.3 0.3 1.0" />
    </material>
    <material name="cam_stand_color">
        <color rgba="0.3 0.3 0.3 1.0" />
    </material>
    <!-- base link -->
    <link name="cam_stand_base_link" />
    <!-- stand base link -->
    <!-- link -->
    <link name="cam_stand_link">
        <visual>
            <origin rpy="1.5707963267948966 0 -1.5707963267948966" xyz="0.0475 0.065 0" />
            <geometry>
                <mesh filename="package://tools_description/meshes/camera_stand/camera_stand_base.STL" scale="0.001 0.001 0.001" />
            </geometry>
            <material name="cam_stand_color" />
        </visual>
        <collision>
            <origin rpy="0 0 0" xyz="0 0 0.505" />
            <geometry>
                <box size="0.1 0.1 1.010" />
            </geometry>
        </collision>
        <inertial>
            <mass value="0.1" />
            <origin xyz="0 0 0" rpy="0 0 0" />
            <inertia ixx="0.03" iyy="0.03" izz="0.03" ixy="0.0" ixz="0.0" iyz="0.0" />
        </inertial>
    </link>
    <!-- joint -->
    <joint name="camera_base-stand_joint" type="fixed">
        <parent link="cam_stand_base_link" />
        <child link="cam_stand_link" />
        <origin rpy="0 0 0" xyz="0 0 0" />
    </joint>
    <!-- stand arm link -->
    <!-- link -->
    <link name="cam_stand_arm_link">
        <visual>
            <origin rpy="1.5707963267948966 0 -1.5707963267948966" xyz="0.32 0.035 -0.081" />
            <geometry>
                <mesh filename="package://tools_description/meshes/camera_stand/camera_stand_arm.STL" scale="0.001 0.001 0.001" />
            </geometry>
            <material name="camera_light_gray" />
        </visual>
        <collision>
            <origin rpy="0 0 0" xyz="0.16 0 0" />
            <geometry>
                <box size="0.320 0.05 0.05" />
            </geometry>
        </collision>
        <inertial>
            <mass value="0.1" />
            <origin xyz="0 0 0" rpy="0 0 0" />
            <inertia ixx="0.03" iyy="0.03" izz="0.03" ixy="0.0" ixz="0.0" iyz="0.0" />
        </inertial>
    </link>
    <!-- joint -->
    <joint name="camera_base-arm_joint" type="fixed">
        <parent link="cam_stand_link" />
        <child link="cam_stand_arm_link" />
        <origin rpy="0 0 0" xyz="0 0 0.9985" />
    </joint>
    <!-- mount link -->
    <!-- link -->
    <link name="cam_stage_mount_link">
        <visual>
            <origin rpy="1.5707963267948966 0 1.5707963267948966" xyz="-0.043 -0.035 -0.043" />
            <geometry>
                <mesh filename="package://tools_description/meshes/camera_stand/camera_stage_mount.STL" scale="0.001 0.001 0.001" />
            </geometry>
            <material name="camera_white" />
        </visual>
        <collision>
            <origin rpy="0 0 0" xyz="0 0 0.009" />
            <geometry>
                <box size="0.086 0.070 0.105" />
            </geometry>
        </collision>
        <inertial>
            <mass value="0.1" />
            <origin xyz="0 0 0" rpy="0 0 0" />
            <inertia ixx="0.03" iyy="0.03" izz="0.03" ixy="0.0" ixz="0.0" iyz="0.0" />
        </inertial>
    </link>
    <!-- joint -->
    <joint name="camera_arm-stage_mount_joint" type="fixed">
        <parent link="cam_stand_arm_link" />
        <child link="cam_stage_mount_link" />
        <origin rpy="0 0 0" xyz="0.277 0 0" />
    </joint>
    <!-- stage link -->
    <link name="cam_stage_link">
        <visual>
            <origin rpy="0 0 0" xyz="0 0.01235 0" />
            <geometry>
                <box size="0.080 0.0247 0.080" />
            </geometry>
            <material name="camera_white" />
        </visual>
        <collision>
            <origin rpy="0 0 0" xyz="0 0.01235 0" />
            <geometry>
                <box size="0.080 0.0247 0.080" />
            </geometry>
        </collision>
        <inertial>
            <mass value="0.1" />
            <origin xyz="0 0 0" rpy="0 0 0" />
            <inertia ixx="0.03" iyy="0.03" izz="0.03" ixy="0.0" ixz="0.0" iyz="0.0" />
        </inertial>
    </link>
    <!-- joint -->
    <joint name="camera_stand_mount-stage_joint" type="fixed">
        <parent link="cam_stage_mount_link" />
        <child link="cam_stage_link" />
        <origin rpy="-0.04 0 -0.01" xyz="0 0.032 0" />
    </joint>
    <!-- mount link -->
    <link name="cam_mount_link">
        <visual>
            <!-- <origin xyz="0.04  0 -0.055" rpy="${PI/2} -${PI/2} ${PI}"/> -->
            <origin rpy="1.5707963267948966 -1.5707963267948966 3.141592653589793" xyz="-0.055 0 -0.04" />
            <geometry>
                <mesh filename="package://tools_description/meshes/camera_stand/camera_mount.STL" scale="0.001 0.001 0.001" />
            </geometry>
            <material name="camera_white" />
        </visual>
        <collision>
            <origin rpy="0 0 0" xyz="0 0.02 0" />
            <geometry>
                <box size="0.080 0.040 0.110" />
            </geometry>
        </collision>
        <inertial>
            <mass value="0.1" />
            <origin xyz="0 0 0" rpy="0 0 0" />
            <inertia ixx="0.03" iyy="0.03" izz="0.03" ixy="0.0" ixz="0.0" iyz="0.0" />
        </inertial>
    </link>
    <!-- joint -->
    <joint name="camera_stage-mount_joint" type="fixed">
        <parent link="cam_stage_link" />
        <child link="cam_mount_link" />
        <origin rpy="0 -0.3490658503988659 0" xyz="0 0.0247 0" />
    </joint>
    <!-- link for camera joint -->
    <!-- link -->
    <link name="cam_link" />
    <!-- joint -->
    <joint name="camera_mount_cam_joint" type="fixed">
        <parent link="cam_mount_link" />
        <child link="cam_link" />
        <origin rpy="1.5707963267948966 1.5707963267948966 0" xyz="0 0.030 -0.04" />
    </joint>
    <joint name="table-camera_stand_joint" type="fixed">
        <parent link="world_base" />
        <child link="cam_stand_base_link" />
        <origin rpy="0.0000 0.0000 3.141592653589793" xyz="0.7240 0.0505 0.0000" />
    </joint>
    <transmission name="trans_finger_hinge_1_joint">
        <type>transmission_interface/SimpleTransmission</type>
        <joint name="finger_hinge_1_joint">
            <hardwareInterface>hardware_interface/EffortJointInterface</hardwareInterface>
        </joint>
        <actuator name="finger_hinge_1_joint_motor">
            <hardwareInterface>hardware_interface/EffortJointInterface</hardwareInterface>
            <mechanicalReduction>1</mechanicalReduction>
        </actuator>
    </transmission>
    <transmission name="trans_finger_hinge_2_joint">
        <type>transmission_interface/SimpleTransmission</type>
        <joint name="finger_hinge_2_joint">
            <hardwareInterface>hardware_interface/EffortJointInterface</hardwareInterface>
        </joint>
        <actuator name="finger_hinge_2_joint_motor">
            <hardwareInterface>hardware_interface/EffortJointInterface</hardwareInterface>
            <mechanicalReduction>1</mechanicalReduction>
        </actuator>
    </transmission>
    <transmission name="trans_finger_hinge_3_joint">
        <type>transmission_interface/SimpleTransmission</type>
        <joint name="finger_hinge_3_joint">
            <hardwareInterface>hardware_interface/EffortJointInterface</hardwareInterface>
        </joint>
        <actuator name="finger_hinge_3_joint_motor">
            <hardwareInterface>hardware_interface/EffortJointInterface</hardwareInterface>
            <mechanicalReduction>1</mechanicalReduction>
        </actuator>
    </transmission>
    <transmission name="trans_finger_1_1_joint">
        <type>transmission_interface/SimpleTransmission</type>
        <joint name="finger_1_1_joint">
            <hardwareInterface>hardware_interface/EffortJointInterface</hardwareInterface>
        </joint>
        <actuator name="finger_1_1_joint_motor">
            <hardwareInterface>hardware_interface/EffortJointInterface</hardwareInterface>
            <mechanicalReduction>1</mechanicalReduction>
        </actuator>
    </transmission>
    <transmission name="trans_finger_1_2_joint">
        <type>transmission_interface/SimpleTransmission</type>
        <joint name="finger_1_2_joint">
            <hardwareInterface>hardware_interface/EffortJointInterface</hardwareInterface>
        </joint>
        <actuator name="finger_1_2_joint_motor">
            <hardwareInterface>hardware_interface/EffortJointInterface</hardwareInterface>
            <mechanicalReduction>1</mechanicalReduction>
        </actuator>
    </transmission>
    <transmission name="trans_finger_2_1_joint">
        <type>transmission_interface/SimpleTransmission</type>
        <joint name="finger_2_1_joint">
            <hardwareInterface>hardware_interface/EffortJointInterface</hardwareInterface>
        </joint>
        <actuator name="finger_2_1_joint_motor">
            <hardwareInterface>hardware_interface/EffortJointInterface</hardwareInterface>
            <mechanicalReduction>1</mechanicalReduction>
        </actuator>
    </transmission>
    <transmission name="trans_finger_2_2_joint">
        <type>transmission_interface/SimpleTransmission</type>
        <joint name="finger_2_2_joint">
            <hardwareInterface>hardware_interface/EffortJointInterface</hardwareInterface>
        </joint>
        <actuator name="finger_2_2_joint_motor">
            <hardwareInterface>hardware_interface/EffortJointInterface</hardwareInterface>
            <mechanicalReduction>1</mechanicalReduction>
        </actuator>
    </transmission>
</robot>

