<?xml version="1.0" encoding="utf-8"?>
<!-- This URDF was automatically created by SolidWorks to URDF Exporter! Originally created by Stephen Brawner (brawner@gmail.com) 
     Commit Version: 1.6.0-4-g7f85cfe  Build Version: 1.6.7995.38578
     For more information, please see http://wiki.ros.org/sw_urdf_exporter -->
<robot
  name="hanyang_gripper_description">
  <link
    name="hanyang_base_link">
    <inertial>
      <origin
        xyz="0.0032794 0.0036243 -0.085843"
        rpy="0 0 0" />
      <mass
        value="1.1991" />
      <inertia
        ixx="0.0032705"
        ixy="-8.8997E-06"
        ixz="5.8891E-09"
        iyy="0.0032572"
        iyz="-1.1733E-07"
        izz="0.0061866" />
    </inertial>
    <visual>
      <origin
        xyz="0 0 0"
        rpy="0 0 0" />
      <geometry>
        <mesh
          filename="package://hanyang_gripper/meshes/base_link.STL" />
      </geometry>
      <material
        name="">
        <color
          rgba="0.79216 0.81961 0.93333 1" />
      </material>
    </visual>
    <collision>
      <origin
        xyz="0 0 0"
        rpy="0 0 0" />
      <geometry>
        <mesh
          filename="package://hanyang_gripper/meshes/base_link.STL" />
      </geometry>
    </collision>
  </link>
  <link
    name="finger_hinge_1_link">
    <inertial>
      <origin
        xyz="0.065641 -0.0079398 -0.0097225"
        rpy="0 0 0" />
      <mass
        value="0.075006" />
      <inertia
        ixx="2.2862E-05"
        ixy="-4.1935E-06"
        ixz="-1.113E-06"
        iyy="2.0983E-05"
        iyz="-2.3625E-06"
        izz="3.2464E-05" />
    </inertial>
    <visual>
      <origin
        xyz="0 0 0"
        rpy="0 0 0" />
      <geometry>
        <mesh
          filename="package://hanyang_gripper/meshes/finger_hinge_1_link.STL" />
      </geometry>
      <material
        name="">
        <color
          rgba="0.79216 0.81961 0.93333 1" />
      </material>
    </visual>
  </link>
  <joint
    name="finger_hinge_1_joint"
    type="prismatic">
    <origin
      xyz="0.13675 -0.0335 -0.115"
      rpy="0 0 -3.1416" />
    <parent
      link="hanyang_base_link" />
    <child
      link="finger_hinge_1_link" />
    <axis
      xyz="-1 0 0" />
    <limit
      lower="0"
      upper="0.129"
      effort="10"
      velocity="10" />
  </joint>
  <link
    name="finger_hinge_2_link">
    <inertial>
      <origin
        xyz="-0.0028372 -2.095E-05 0.057266"
        rpy="0 0 0" />
      <mass
        value="0.067705" />
      <inertia
        ixx="1.3529E-05"
        ixy="1.1024E-06"
        ixz="-2.9156E-06"
        iyy="2.022E-05"
        iyz="7.2143E-07"
        izz="1.741E-05" />
    </inertial>
    <visual>
      <origin
        xyz="0 0 0"
        rpy="0 0 0" />
      <geometry>
        <mesh
          filename="package://hanyang_gripper/meshes/finger_hinge_2_link.STL" />
      </geometry>
      <material
        name="">
        <color
          rgba="0.79216 0.81961 0.93333 1" />
      </material>
    </visual>
  </link>
  <joint
    name="finger_hinge_2_joint"
    type="revolute">
    <origin
      xyz="0.060883 -0.034 -0.0408"
      rpy="-3.1416 0 -3.1416" />
    <parent
      link="finger_hinge_1_link" />
    <child
      link="finger_hinge_2_link" />
    <axis
      xyz="0 1 0" />
    <limit
      lower="-1.570796"
      upper="0"
      effort="10"
      velocity="10" />
  </joint>
  <link
    name="finger_hinge_3_link">
    <inertial>
      <origin
        xyz="0.005275 0.0017219 0.027803"
        rpy="0 0 0" />
      <mass
        value="0.024551" />
      <inertia
        ixx="2.8212E-06"
        ixy="4.4824E-09"
        ixz="1.3164E-06"
        iyy="5.5805E-06"
        iyz="-2.68E-08"
        izz="5.0262E-06" />
    </inertial>
    <visual>
      <origin
        xyz="0 0 0"
        rpy="0 0 0" />
      <geometry>
        <mesh
          filename="package://hanyang_gripper/meshes/finger_hinge_3_link.STL" />
      </geometry>
      <material
        name="">
        <color
          rgba="0.79216 0.81961 0.93333 1" />
      </material>
    </visual>
  </link>
  <joint
    name="finger_hinge_3_joint"
    type="revolute">
    <origin
      xyz="-0.013 0.00125 0.1269"
      rpy="0 0 0" />
    <parent
      link="finger_hinge_2_link" />
    <child
      link="finger_hinge_3_link" />
    <axis
      xyz="0 -1 0" />
    <limit
      lower="-0.13963"
      upper="0.349065777777778"
      effort="10"
      velocity="10" />
  </joint>
  <link
    name="finger_1_1_link">
    <inertial>
      <origin
        xyz="0.065932 -0.02114 -0.050052"
        rpy="0 0 0" />
      <mass
        value="0.15457" />
      <inertia
        ixx="3.8904E-05"
        ixy="-1.1423E-06"
        ixz="-2.8992E-06"
        iyy="4.546E-05"
        iyz="-7.4443E-07"
        izz="4.8395E-05" />
    </inertial>
    <visual>
      <origin
        xyz="0 0 0"
        rpy="0 0 0" />
      <geometry>
        <mesh
          filename="package://hanyang_gripper/meshes/finger_1_1_link.STL" />
      </geometry>
      <material
        name="">
        <color
          rgba="0.79216 0.81961 0.93333 1" />
      </material>
    </visual>
  </link>
  <joint
    name="finger_1_1_joint"
    type="prismatic">
    <origin
      xyz="-0.097387 -0.10168 -0.115"
      rpy="0 0 1.0472" />
    <parent
      link="hanyang_base_link" />
    <child
      link="finger_1_1_link" />
    <axis
      xyz="-1 0 0" />
    <limit
      lower="0"
      upper="0.129"
      effort="10"
      velocity="10" />
  </joint>
  <link
    name="finger_1_2_link">
    <inertial>
      <origin
        xyz="-0.010542 0.0017219 -0.027803"
        rpy="0 0 0" />
      <mass
        value="0.024551" />
      <inertia
        ixx="2.8212E-06"
        ixy="-4.4826E-09"
        ixz="1.3164E-06"
        iyy="5.5805E-06"
        iyz="2.6801E-08"
        izz="5.0262E-06" />
    </inertial>
    <visual>
      <origin
        xyz="0 0 0"
        rpy="0 0 0" />
      <geometry>
        <mesh
          filename="package://hanyang_gripper/meshes/finger_1_2_link.STL" />
      </geometry>
      <material
        name="">
        <color
          rgba="0.79216 0.81961 0.93333 1" />
      </material>
    </visual>
  </link>
  <joint
    name="finger_1_2_joint"
    type="revolute">
    <origin
      xyz="0.07675 -0.03275 -0.168"
      rpy="0 0 0" />
    <parent
      link="finger_1_1_link" />
    <child
      link="finger_1_2_link" />
    <axis
      xyz="0 -1 0" />
    <limit
      lower="-0.13963"
      upper="0.349065777777778"
      effort="10"
      velocity="10" />
  </joint>
  <link
    name="finger_2_1_link">
    <inertial>
      <origin
        xyz="0.065932 -0.02114 -0.050052"
        rpy="0 0 0" />
      <mass
        value="0.15457" />
      <inertia
        ixx="3.8904E-05"
        ixy="-1.1423E-06"
        ixz="-2.8992E-06"
        iyy="4.546E-05"
        iyz="-7.4443E-07"
        izz="4.8395E-05" />
    </inertial>
    <visual>
      <origin
        xyz="0 0 0"
        rpy="0 0 0" />
      <geometry>
        <mesh
          filename="package://hanyang_gripper/meshes/finger_2_1_link.STL" />
      </geometry>
      <material
        name="">
        <color
          rgba="0.79216 0.81961 0.93333 1" />
      </material>
    </visual>
  </link>
  <joint
    name="finger_2_1_joint"
    type="prismatic">
    <origin
      xyz="-0.039363 0.13518 -0.115"
      rpy="0 0 -1.0472" />
    <parent
      link="hanyang_base_link" />
    <child
      link="finger_2_1_link" />
    <axis
      xyz="-1 0 0" />
    <limit
      lower="0"
      upper="0.129"
      effort="10"
      velocity="10" />
  </joint>
  <link
    name="finger_2_2_link">
    <inertial>
      <origin
        xyz="-0.010542 0.0017219 -0.027803"
        rpy="0 0 0" />
      <mass
        value="0.024551" />
      <inertia
        ixx="2.8212E-06"
        ixy="-4.4824E-09"
        ixz="1.3164E-06"
        iyy="5.5805E-06"
        iyz="2.68E-08"
        izz="5.0262E-06" />
    </inertial>
    <visual>
      <origin
        xyz="0 0 0"
        rpy="0 0 0" />
      <geometry>
        <mesh
          filename="package://hanyang_gripper/meshes/finger_2_2_link.STL" />
      </geometry>
      <material
        name="">
        <color
          rgba="0.79216 0.81961 0.93333 1" />
      </material>
    </visual>
  </link>
  <joint
    name="finger_2_2_joint"
    type="revolute">
    <origin
      xyz="0.07675 -0.03275 -0.168"
      rpy="0 0 0" />
    <parent
      link="finger_2_1_link" />
    <child
      link="finger_2_2_link" />
    <axis
      xyz="0 -1 0" />
    <limit
      lower="-0.13963"
      upper="0.349065777777778"
      effort="10"
      velocity="10" />
  </joint>
</robot>